{
  "nbformat": 4,
  "nbformat_minor": 0,
  "metadata": {
    "colab": {
      "provenance": []
    },
    "kernelspec": {
      "name": "python3",
      "display_name": "Python 3"
    },
    "language_info": {
      "name": "python"
    }
  },
  "cells": [
    {
      "cell_type": "code",
      "execution_count": null,
      "metadata": {
        "id": "679RsX6AZ56k",
        "colab": {
          "base_uri": "https://localhost:8080/"
        },
        "outputId": "a2ef72e9-657e-4510-be00-f35c69510033"
      },
      "outputs": [
        {
          "output_type": "execute_result",
          "data": {
            "text/plain": [
              "5"
            ]
          },
          "metadata": {},
          "execution_count": 1
        }
      ],
      "source": [
        "3+2"
      ]
    },
    {
      "cell_type": "code",
      "source": [
        "!python"
      ],
      "metadata": {
        "colab": {
          "base_uri": "https://localhost:8080/"
        },
        "id": "JkArbAu6g-dD",
        "outputId": "5634539b-8688-46fd-8af3-7251c7dc9af8"
      },
      "execution_count": null,
      "outputs": [
        {
          "output_type": "stream",
          "name": "stdout",
          "text": [
            "Python 3.10.12 (main, Mar 22 2024, 16:50:05) [GCC 11.4.0] on linux\n",
            "Type \"help\", \"copyright\", \"credits\" or \"license\" for more information.\n",
            ">>> \n",
            "KeyboardInterrupt\n",
            ">>> \n",
            "KeyboardInterrupt\n",
            ">>> \n",
            "KeyboardInterrupt\n",
            ">>> ^C\n"
          ]
        }
      ]
    },
    {
      "cell_type": "markdown",
      "source": [
        "Сегодня мне было ок"
      ],
      "metadata": {
        "id": "zWPhN2c7hJZE"
      }
    },
    {
      "cell_type": "code",
      "source": [
        "!pip install telebot"
      ],
      "metadata": {
        "id": "zuSQz5QkQo8e"
      },
      "execution_count": null,
      "outputs": []
    },
    {
      "cell_type": "code",
      "source": [
        "print(\"Hello Karpov courses!\")"
      ],
      "metadata": {
        "colab": {
          "base_uri": "https://localhost:8080/"
        },
        "id": "ygMozCjZhVA9",
        "outputId": "0716b3f2-00d7-4979-d155-1a19e642966a"
      },
      "execution_count": null,
      "outputs": [
        {
          "output_type": "stream",
          "name": "stdout",
          "text": [
            "Hello Karpov courses!\n"
          ]
        }
      ]
    },
    {
      "cell_type": "code",
      "source": [
        "a = 5\n",
        "b = 6\n",
        "print(a+b)\n",
        "print(type(a))"
      ],
      "metadata": {
        "colab": {
          "base_uri": "https://localhost:8080/"
        },
        "id": "GcFux88MhsbP",
        "outputId": "a4d1eb40-c84c-4459-ead3-5270d4697751"
      },
      "execution_count": null,
      "outputs": [
        {
          "output_type": "stream",
          "name": "stdout",
          "text": [
            "11\n",
            "<class 'int'>\n"
          ]
        }
      ]
    },
    {
      "cell_type": "code",
      "source": [
        "print(a+b)\n",
        "print(a-b)\n",
        "print(a*b)\n",
        "print(a//b)\n",
        "print(a%b)\n",
        "print(a**b)"
      ],
      "metadata": {
        "colab": {
          "base_uri": "https://localhost:8080/"
        },
        "id": "Sm5RCZBCiTU5",
        "outputId": "fc887663-dfd5-46f5-9191-ab5edf59fd9c"
      },
      "execution_count": null,
      "outputs": [
        {
          "output_type": "stream",
          "name": "stdout",
          "text": [
            "11\n",
            "-1\n",
            "30\n",
            "0\n",
            "5\n",
            "15625\n"
          ]
        }
      ]
    },
    {
      "cell_type": "code",
      "source": [
        "a = int(input(\"Введите число\"))\n",
        "print(a**2)"
      ],
      "metadata": {
        "colab": {
          "base_uri": "https://localhost:8080/"
        },
        "id": "nN7tuGseipZ5",
        "outputId": "ac5d3b9b-c7c2-42c4-b578-9685746ef926"
      },
      "execution_count": null,
      "outputs": [
        {
          "output_type": "stream",
          "name": "stdout",
          "text": [
            "Введите число5\n",
            "25\n"
          ]
        }
      ]
    },
    {
      "cell_type": "markdown",
      "source": [
        "п р и в е т к а р п о в к у р с е с"
      ],
      "metadata": {
        "id": "j0VM-MDhjF3S"
      }
    },
    {
      "cell_type": "code",
      "source": [
        "name = \"Звездные войны\""
      ],
      "metadata": {
        "id": "-0vek_ajjDZG"
      },
      "execution_count": null,
      "outputs": []
    },
    {
      "cell_type": "code",
      "source": [
        "word = \"рентгеноэлектрокардиографического\"\n",
        "print(word[-1], word[3], sep=\"\")\n"
      ],
      "metadata": {
        "colab": {
          "base_uri": "https://localhost:8080/"
        },
        "id": "QmWlr42njhpb",
        "outputId": "d68b7710-178e-4e7d-9295-b45844f0123e"
      },
      "execution_count": null,
      "outputs": [
        {
          "output_type": "stream",
          "name": "stdout",
          "text": [
            "от\n"
          ]
        }
      ]
    },
    {
      "cell_type": "code",
      "source": [
        "word = \"рентгеноэлектрокардиографического\"\n",
        "print(word[:7:2])\n",
        "print(word[::-1])"
      ],
      "metadata": {
        "colab": {
          "base_uri": "https://localhost:8080/"
        },
        "id": "MfDA1lHAlSjE",
        "outputId": "7279b49f-48ba-4916-ca5b-dc5747a2d8be"
      },
      "execution_count": null,
      "outputs": [
        {
          "output_type": "stream",
          "name": "stdout",
          "text": [
            "рнгн\n",
            "огоксечифаргоидракорткелэонегтнер\n"
          ]
        }
      ]
    },
    {
      "cell_type": "markdown",
      "source": [
        "Выведите каждый третий элемент, начиная с 4 до 15 включительно"
      ],
      "metadata": {
        "id": "BrZ202MTl-bq"
      }
    },
    {
      "cell_type": "code",
      "source": [
        "print(word[4:16:3])"
      ],
      "metadata": {
        "colab": {
          "base_uri": "https://localhost:8080/"
        },
        "id": "rqj7L9_SmF8_",
        "outputId": "a37e5119-1dce-49d5-c29f-190037ec5548"
      },
      "execution_count": null,
      "outputs": [
        {
          "output_type": "stream",
          "name": "stdout",
          "text": [
            "гоер\n"
          ]
        }
      ]
    },
    {
      "cell_type": "code",
      "source": [
        "a = 5\n",
        "b = 6\n",
        "if a > 4:\n",
        "  print(\"Ого, больше 4\")\n",
        "else:\n",
        "  print(\"Эх, меньше 4\")"
      ],
      "metadata": {
        "colab": {
          "base_uri": "https://localhost:8080/"
        },
        "id": "BCJST3P2mjyF",
        "outputId": "d9f85059-46ba-4d3d-ec52-51a4ca424e21"
      },
      "execution_count": null,
      "outputs": [
        {
          "output_type": "stream",
          "name": "stdout",
          "text": [
            "Ого, больше 4\n"
          ]
        }
      ]
    },
    {
      "cell_type": "code",
      "source": [
        "a = int(input())\n",
        "if a % 2 == 0:\n",
        "  print(\"Четное\")\n",
        "  print(a)\n",
        "elif a % 3 == 0:\n",
        "  print(\"Делится на три\")\n",
        "else:\n",
        "  print(\"NOT Четное\")"
      ],
      "metadata": {
        "colab": {
          "base_uri": "https://localhost:8080/"
        },
        "id": "H3rJtylcnMmv",
        "outputId": "5ab5dcf1-5c3e-4ae6-dde7-989d6196b9d4"
      },
      "execution_count": null,
      "outputs": [
        {
          "output_type": "stream",
          "name": "stdout",
          "text": [
            "4\n",
            "Четное\n",
            "4\n"
          ]
        }
      ]
    },
    {
      "cell_type": "code",
      "source": [
        "a = int(input())\n",
        "while a % 2 == 0:\n",
        "  print(\"OK\")\n",
        "  a = int(input())\n",
        "print(\"NOT OK\")"
      ],
      "metadata": {
        "colab": {
          "base_uri": "https://localhost:8080/"
        },
        "id": "PHlOyj7DnzfD",
        "outputId": "7820f1f8-2d7d-42e0-fb7b-b43080c9e1f5"
      },
      "execution_count": null,
      "outputs": [
        {
          "output_type": "stream",
          "name": "stdout",
          "text": [
            "4\n",
            "OK\n",
            "8\n",
            "OK\n",
            "0\n",
            "OK\n",
            "3\n",
            "NOT OK\n"
          ]
        }
      ]
    },
    {
      "cell_type": "code",
      "source": [
        "for i in range(3):\n",
        "  print(i)\n",
        "  print(\"Беру мармеладку\")"
      ],
      "metadata": {
        "colab": {
          "base_uri": "https://localhost:8080/"
        },
        "id": "IkVZgZ8moPfh",
        "outputId": "9736204e-715c-442d-b4aa-3a647010c5dd"
      },
      "execution_count": null,
      "outputs": [
        {
          "output_type": "stream",
          "name": "stdout",
          "text": [
            "0\n",
            "Беру мармеладку\n",
            "1\n",
            "Беру мармеладку\n",
            "2\n",
            "Беру мармеладку\n"
          ]
        }
      ]
    },
    {
      "cell_type": "code",
      "source": [
        "!pip install telebot"
      ],
      "metadata": {
        "colab": {
          "base_uri": "https://localhost:8080/"
        },
        "id": "tsBvSIwloqjh",
        "outputId": "c52369f9-2291-46dc-cbbb-248433a476e0"
      },
      "execution_count": null,
      "outputs": [
        {
          "output_type": "stream",
          "name": "stdout",
          "text": [
            "Collecting telebot\n",
            "  Downloading telebot-0.0.5-py3-none-any.whl (4.8 kB)\n",
            "Collecting pyTelegramBotAPI (from telebot)\n",
            "  Downloading pytelegrambotapi-4.21.0-py3-none-any.whl (250 kB)\n",
            "\u001b[2K     \u001b[90m━━━━━━━━━━━━━━━━━━━━━━━━━━━━━━━━━━━━━━━━\u001b[0m \u001b[32m250.5/250.5 kB\u001b[0m \u001b[31m4.8 MB/s\u001b[0m eta \u001b[36m0:00:00\u001b[0m\n",
            "\u001b[?25hRequirement already satisfied: requests in /usr/local/lib/python3.10/dist-packages (from telebot) (2.31.0)\n",
            "Requirement already satisfied: charset-normalizer<4,>=2 in /usr/local/lib/python3.10/dist-packages (from requests->telebot) (3.3.2)\n",
            "Requirement already satisfied: idna<4,>=2.5 in /usr/local/lib/python3.10/dist-packages (from requests->telebot) (3.7)\n",
            "Requirement already satisfied: urllib3<3,>=1.21.1 in /usr/local/lib/python3.10/dist-packages (from requests->telebot) (2.0.7)\n",
            "Requirement already satisfied: certifi>=2017.4.17 in /usr/local/lib/python3.10/dist-packages (from requests->telebot) (2024.7.4)\n",
            "Installing collected packages: pyTelegramBotAPI, telebot\n",
            "Successfully installed pyTelegramBotAPI-4.21.0 telebot-0.0.5\n"
          ]
        }
      ]
    },
    {
      "cell_type": "code",
      "source": [
        "import telebot\n",
        "\n",
        "API_TOKEN = '7006358365:AAE2eRsaTKJRzVXrK4lkJUwP6S-_GDByRJI'\n",
        "\n",
        "bot = telebot.TeleBot(API_TOKEN)\n",
        "\n",
        "\n",
        "# Handle '/start' and '/help'\n",
        "@bot.message_handler(commands=['help', 'start'])\n",
        "def send_welcome(message):\n",
        "    bot.reply_to(message, \"\"\"\\\n",
        "Hi there, I am EchoBot.\n",
        "I am here to echo your kind words back to you. Just say anything nice and I'll say the exact same thing to you!\\\n",
        "\"\"\")\n",
        "\n",
        "\n",
        "# Handle all other messages with content_type 'text' (content_types defaults to ['text'])\n",
        "@bot.message_handler(func=lambda message: True)\n",
        "def echo_message(message):\n",
        "    bot.reply_to(message, message.text)\n",
        "\n",
        "\n",
        "bot.infinity_polling()"
      ],
      "metadata": {
        "colab": {
          "base_uri": "https://localhost:8080/",
          "height": 1000
        },
        "id": "4-zIHf1fQh6G",
        "outputId": "9bd7bfd3-dca2-495a-aed1-94a2aa115d9f"
      },
      "execution_count": null,
      "outputs": [
        {
          "output_type": "stream",
          "name": "stderr",
          "text": [
            "2024-07-17 17:04:55,370 (__init__.py:1221 MainThread) ERROR - TeleBot: \"Threaded polling exception: A request to the Telegram API was unsuccessful. Error code: 409. Description: Conflict: terminated by other getUpdates request; make sure that only one bot instance is running\"\n",
            "ERROR:TeleBot:Threaded polling exception: A request to the Telegram API was unsuccessful. Error code: 409. Description: Conflict: terminated by other getUpdates request; make sure that only one bot instance is running\n",
            "2024-07-17 17:04:55,374 (__init__.py:1223 MainThread) ERROR - TeleBot: \"Exception traceback:\n",
            "Traceback (most recent call last):\n",
            "  File \"/usr/local/lib/python3.10/dist-packages/telebot/__init__.py\", line 1214, in __threaded_polling\n",
            "    polling_thread.raise_exceptions()\n",
            "  File \"/usr/local/lib/python3.10/dist-packages/telebot/util.py\", line 111, in raise_exceptions\n",
            "    raise self.exception_info\n",
            "  File \"/usr/local/lib/python3.10/dist-packages/telebot/util.py\", line 93, in run\n",
            "    task(*args, **kwargs)\n",
            "  File \"/usr/local/lib/python3.10/dist-packages/telebot/__init__.py\", line 676, in __retrieve_updates\n",
            "    updates = self.get_updates(offset=(self.last_update_id + 1),\n",
            "  File \"/usr/local/lib/python3.10/dist-packages/telebot/__init__.py\", line 648, in get_updates\n",
            "    json_updates = apihelper.get_updates(\n",
            "  File \"/usr/local/lib/python3.10/dist-packages/telebot/apihelper.py\", line 330, in get_updates\n",
            "    return _make_request(token, method_url, params=payload)\n",
            "  File \"/usr/local/lib/python3.10/dist-packages/telebot/apihelper.py\", line 168, in _make_request\n",
            "    json_result = _check_result(method_name, result)\n",
            "  File \"/usr/local/lib/python3.10/dist-packages/telebot/apihelper.py\", line 195, in _check_result\n",
            "    raise ApiTelegramException(method_name, result, result_json)\n",
            "telebot.apihelper.ApiTelegramException: A request to the Telegram API was unsuccessful. Error code: 409. Description: Conflict: terminated by other getUpdates request; make sure that only one bot instance is running\n",
            "\"\n",
            "ERROR:TeleBot:Exception traceback:\n",
            "Traceback (most recent call last):\n",
            "  File \"/usr/local/lib/python3.10/dist-packages/telebot/__init__.py\", line 1214, in __threaded_polling\n",
            "    polling_thread.raise_exceptions()\n",
            "  File \"/usr/local/lib/python3.10/dist-packages/telebot/util.py\", line 111, in raise_exceptions\n",
            "    raise self.exception_info\n",
            "  File \"/usr/local/lib/python3.10/dist-packages/telebot/util.py\", line 93, in run\n",
            "    task(*args, **kwargs)\n",
            "  File \"/usr/local/lib/python3.10/dist-packages/telebot/__init__.py\", line 676, in __retrieve_updates\n",
            "    updates = self.get_updates(offset=(self.last_update_id + 1),\n",
            "  File \"/usr/local/lib/python3.10/dist-packages/telebot/__init__.py\", line 648, in get_updates\n",
            "    json_updates = apihelper.get_updates(\n",
            "  File \"/usr/local/lib/python3.10/dist-packages/telebot/apihelper.py\", line 330, in get_updates\n",
            "    return _make_request(token, method_url, params=payload)\n",
            "  File \"/usr/local/lib/python3.10/dist-packages/telebot/apihelper.py\", line 168, in _make_request\n",
            "    json_result = _check_result(method_name, result)\n",
            "  File \"/usr/local/lib/python3.10/dist-packages/telebot/apihelper.py\", line 195, in _check_result\n",
            "    raise ApiTelegramException(method_name, result, result_json)\n",
            "telebot.apihelper.ApiTelegramException: A request to the Telegram API was unsuccessful. Error code: 409. Description: Conflict: terminated by other getUpdates request; make sure that only one bot instance is running\n",
            "\n",
            "2024-07-17 17:04:59,319 (__init__.py:1221 MainThread) ERROR - TeleBot: \"Threaded polling exception: A request to the Telegram API was unsuccessful. Error code: 409. Description: Conflict: terminated by other getUpdates request; make sure that only one bot instance is running\"\n",
            "ERROR:TeleBot:Threaded polling exception: A request to the Telegram API was unsuccessful. Error code: 409. Description: Conflict: terminated by other getUpdates request; make sure that only one bot instance is running\n",
            "2024-07-17 17:04:59,324 (__init__.py:1223 MainThread) ERROR - TeleBot: \"Exception traceback:\n",
            "Traceback (most recent call last):\n",
            "  File \"/usr/local/lib/python3.10/dist-packages/telebot/__init__.py\", line 1214, in __threaded_polling\n",
            "    polling_thread.raise_exceptions()\n",
            "  File \"/usr/local/lib/python3.10/dist-packages/telebot/util.py\", line 111, in raise_exceptions\n",
            "    raise self.exception_info\n",
            "  File \"/usr/local/lib/python3.10/dist-packages/telebot/util.py\", line 93, in run\n",
            "    task(*args, **kwargs)\n",
            "  File \"/usr/local/lib/python3.10/dist-packages/telebot/__init__.py\", line 676, in __retrieve_updates\n",
            "    updates = self.get_updates(offset=(self.last_update_id + 1),\n",
            "  File \"/usr/local/lib/python3.10/dist-packages/telebot/__init__.py\", line 648, in get_updates\n",
            "    json_updates = apihelper.get_updates(\n",
            "  File \"/usr/local/lib/python3.10/dist-packages/telebot/apihelper.py\", line 330, in get_updates\n",
            "    return _make_request(token, method_url, params=payload)\n",
            "  File \"/usr/local/lib/python3.10/dist-packages/telebot/apihelper.py\", line 168, in _make_request\n",
            "    json_result = _check_result(method_name, result)\n",
            "  File \"/usr/local/lib/python3.10/dist-packages/telebot/apihelper.py\", line 195, in _check_result\n",
            "    raise ApiTelegramException(method_name, result, result_json)\n",
            "telebot.apihelper.ApiTelegramException: A request to the Telegram API was unsuccessful. Error code: 409. Description: Conflict: terminated by other getUpdates request; make sure that only one bot instance is running\n",
            "\"\n",
            "ERROR:TeleBot:Exception traceback:\n",
            "Traceback (most recent call last):\n",
            "  File \"/usr/local/lib/python3.10/dist-packages/telebot/__init__.py\", line 1214, in __threaded_polling\n",
            "    polling_thread.raise_exceptions()\n",
            "  File \"/usr/local/lib/python3.10/dist-packages/telebot/util.py\", line 111, in raise_exceptions\n",
            "    raise self.exception_info\n",
            "  File \"/usr/local/lib/python3.10/dist-packages/telebot/util.py\", line 93, in run\n",
            "    task(*args, **kwargs)\n",
            "  File \"/usr/local/lib/python3.10/dist-packages/telebot/__init__.py\", line 676, in __retrieve_updates\n",
            "    updates = self.get_updates(offset=(self.last_update_id + 1),\n",
            "  File \"/usr/local/lib/python3.10/dist-packages/telebot/__init__.py\", line 648, in get_updates\n",
            "    json_updates = apihelper.get_updates(\n",
            "  File \"/usr/local/lib/python3.10/dist-packages/telebot/apihelper.py\", line 330, in get_updates\n",
            "    return _make_request(token, method_url, params=payload)\n",
            "  File \"/usr/local/lib/python3.10/dist-packages/telebot/apihelper.py\", line 168, in _make_request\n",
            "    json_result = _check_result(method_name, result)\n",
            "  File \"/usr/local/lib/python3.10/dist-packages/telebot/apihelper.py\", line 195, in _check_result\n",
            "    raise ApiTelegramException(method_name, result, result_json)\n",
            "telebot.apihelper.ApiTelegramException: A request to the Telegram API was unsuccessful. Error code: 409. Description: Conflict: terminated by other getUpdates request; make sure that only one bot instance is running\n",
            "\n",
            "2024-07-17 17:05:03,526 (__init__.py:1221 MainThread) ERROR - TeleBot: \"Threaded polling exception: A request to the Telegram API was unsuccessful. Error code: 409. Description: Conflict: terminated by other getUpdates request; make sure that only one bot instance is running\"\n",
            "ERROR:TeleBot:Threaded polling exception: A request to the Telegram API was unsuccessful. Error code: 409. Description: Conflict: terminated by other getUpdates request; make sure that only one bot instance is running\n",
            "2024-07-17 17:05:03,530 (__init__.py:1223 MainThread) ERROR - TeleBot: \"Exception traceback:\n",
            "Traceback (most recent call last):\n",
            "  File \"/usr/local/lib/python3.10/dist-packages/telebot/__init__.py\", line 1214, in __threaded_polling\n",
            "    polling_thread.raise_exceptions()\n",
            "  File \"/usr/local/lib/python3.10/dist-packages/telebot/util.py\", line 111, in raise_exceptions\n",
            "    raise self.exception_info\n",
            "  File \"/usr/local/lib/python3.10/dist-packages/telebot/util.py\", line 93, in run\n",
            "    task(*args, **kwargs)\n",
            "  File \"/usr/local/lib/python3.10/dist-packages/telebot/__init__.py\", line 676, in __retrieve_updates\n",
            "    updates = self.get_updates(offset=(self.last_update_id + 1),\n",
            "  File \"/usr/local/lib/python3.10/dist-packages/telebot/__init__.py\", line 648, in get_updates\n",
            "    json_updates = apihelper.get_updates(\n",
            "  File \"/usr/local/lib/python3.10/dist-packages/telebot/apihelper.py\", line 330, in get_updates\n",
            "    return _make_request(token, method_url, params=payload)\n",
            "  File \"/usr/local/lib/python3.10/dist-packages/telebot/apihelper.py\", line 168, in _make_request\n",
            "    json_result = _check_result(method_name, result)\n",
            "  File \"/usr/local/lib/python3.10/dist-packages/telebot/apihelper.py\", line 195, in _check_result\n",
            "    raise ApiTelegramException(method_name, result, result_json)\n",
            "telebot.apihelper.ApiTelegramException: A request to the Telegram API was unsuccessful. Error code: 409. Description: Conflict: terminated by other getUpdates request; make sure that only one bot instance is running\n",
            "\"\n",
            "ERROR:TeleBot:Exception traceback:\n",
            "Traceback (most recent call last):\n",
            "  File \"/usr/local/lib/python3.10/dist-packages/telebot/__init__.py\", line 1214, in __threaded_polling\n",
            "    polling_thread.raise_exceptions()\n",
            "  File \"/usr/local/lib/python3.10/dist-packages/telebot/util.py\", line 111, in raise_exceptions\n",
            "    raise self.exception_info\n",
            "  File \"/usr/local/lib/python3.10/dist-packages/telebot/util.py\", line 93, in run\n",
            "    task(*args, **kwargs)\n",
            "  File \"/usr/local/lib/python3.10/dist-packages/telebot/__init__.py\", line 676, in __retrieve_updates\n",
            "    updates = self.get_updates(offset=(self.last_update_id + 1),\n",
            "  File \"/usr/local/lib/python3.10/dist-packages/telebot/__init__.py\", line 648, in get_updates\n",
            "    json_updates = apihelper.get_updates(\n",
            "  File \"/usr/local/lib/python3.10/dist-packages/telebot/apihelper.py\", line 330, in get_updates\n",
            "    return _make_request(token, method_url, params=payload)\n",
            "  File \"/usr/local/lib/python3.10/dist-packages/telebot/apihelper.py\", line 168, in _make_request\n",
            "    json_result = _check_result(method_name, result)\n",
            "  File \"/usr/local/lib/python3.10/dist-packages/telebot/apihelper.py\", line 195, in _check_result\n",
            "    raise ApiTelegramException(method_name, result, result_json)\n",
            "telebot.apihelper.ApiTelegramException: A request to the Telegram API was unsuccessful. Error code: 409. Description: Conflict: terminated by other getUpdates request; make sure that only one bot instance is running\n",
            "\n",
            "2024-07-17 17:05:07,745 (__init__.py:1221 MainThread) ERROR - TeleBot: \"Threaded polling exception: A request to the Telegram API was unsuccessful. Error code: 409. Description: Conflict: terminated by other getUpdates request; make sure that only one bot instance is running\"\n",
            "ERROR:TeleBot:Threaded polling exception: A request to the Telegram API was unsuccessful. Error code: 409. Description: Conflict: terminated by other getUpdates request; make sure that only one bot instance is running\n",
            "2024-07-17 17:05:07,749 (__init__.py:1223 MainThread) ERROR - TeleBot: \"Exception traceback:\n",
            "Traceback (most recent call last):\n",
            "  File \"/usr/local/lib/python3.10/dist-packages/telebot/__init__.py\", line 1214, in __threaded_polling\n",
            "    polling_thread.raise_exceptions()\n",
            "  File \"/usr/local/lib/python3.10/dist-packages/telebot/util.py\", line 111, in raise_exceptions\n",
            "    raise self.exception_info\n",
            "  File \"/usr/local/lib/python3.10/dist-packages/telebot/util.py\", line 93, in run\n",
            "    task(*args, **kwargs)\n",
            "  File \"/usr/local/lib/python3.10/dist-packages/telebot/__init__.py\", line 676, in __retrieve_updates\n",
            "    updates = self.get_updates(offset=(self.last_update_id + 1),\n",
            "  File \"/usr/local/lib/python3.10/dist-packages/telebot/__init__.py\", line 648, in get_updates\n",
            "    json_updates = apihelper.get_updates(\n",
            "  File \"/usr/local/lib/python3.10/dist-packages/telebot/apihelper.py\", line 330, in get_updates\n",
            "    return _make_request(token, method_url, params=payload)\n",
            "  File \"/usr/local/lib/python3.10/dist-packages/telebot/apihelper.py\", line 168, in _make_request\n",
            "    json_result = _check_result(method_name, result)\n",
            "  File \"/usr/local/lib/python3.10/dist-packages/telebot/apihelper.py\", line 195, in _check_result\n",
            "    raise ApiTelegramException(method_name, result, result_json)\n",
            "telebot.apihelper.ApiTelegramException: A request to the Telegram API was unsuccessful. Error code: 409. Description: Conflict: terminated by other getUpdates request; make sure that only one bot instance is running\n",
            "\"\n",
            "ERROR:TeleBot:Exception traceback:\n",
            "Traceback (most recent call last):\n",
            "  File \"/usr/local/lib/python3.10/dist-packages/telebot/__init__.py\", line 1214, in __threaded_polling\n",
            "    polling_thread.raise_exceptions()\n",
            "  File \"/usr/local/lib/python3.10/dist-packages/telebot/util.py\", line 111, in raise_exceptions\n",
            "    raise self.exception_info\n",
            "  File \"/usr/local/lib/python3.10/dist-packages/telebot/util.py\", line 93, in run\n",
            "    task(*args, **kwargs)\n",
            "  File \"/usr/local/lib/python3.10/dist-packages/telebot/__init__.py\", line 676, in __retrieve_updates\n",
            "    updates = self.get_updates(offset=(self.last_update_id + 1),\n",
            "  File \"/usr/local/lib/python3.10/dist-packages/telebot/__init__.py\", line 648, in get_updates\n",
            "    json_updates = apihelper.get_updates(\n",
            "  File \"/usr/local/lib/python3.10/dist-packages/telebot/apihelper.py\", line 330, in get_updates\n",
            "    return _make_request(token, method_url, params=payload)\n",
            "  File \"/usr/local/lib/python3.10/dist-packages/telebot/apihelper.py\", line 168, in _make_request\n",
            "    json_result = _check_result(method_name, result)\n",
            "  File \"/usr/local/lib/python3.10/dist-packages/telebot/apihelper.py\", line 195, in _check_result\n",
            "    raise ApiTelegramException(method_name, result, result_json)\n",
            "telebot.apihelper.ApiTelegramException: A request to the Telegram API was unsuccessful. Error code: 409. Description: Conflict: terminated by other getUpdates request; make sure that only one bot instance is running\n",
            "\n",
            "2024-07-17 17:05:12,982 (__init__.py:1221 MainThread) ERROR - TeleBot: \"Threaded polling exception: A request to the Telegram API was unsuccessful. Error code: 409. Description: Conflict: terminated by other getUpdates request; make sure that only one bot instance is running\"\n",
            "ERROR:TeleBot:Threaded polling exception: A request to the Telegram API was unsuccessful. Error code: 409. Description: Conflict: terminated by other getUpdates request; make sure that only one bot instance is running\n",
            "2024-07-17 17:05:12,985 (__init__.py:1223 MainThread) ERROR - TeleBot: \"Exception traceback:\n",
            "Traceback (most recent call last):\n",
            "  File \"/usr/local/lib/python3.10/dist-packages/telebot/__init__.py\", line 1214, in __threaded_polling\n",
            "    polling_thread.raise_exceptions()\n",
            "  File \"/usr/local/lib/python3.10/dist-packages/telebot/util.py\", line 111, in raise_exceptions\n",
            "    raise self.exception_info\n",
            "  File \"/usr/local/lib/python3.10/dist-packages/telebot/util.py\", line 93, in run\n",
            "    task(*args, **kwargs)\n",
            "  File \"/usr/local/lib/python3.10/dist-packages/telebot/__init__.py\", line 676, in __retrieve_updates\n",
            "    updates = self.get_updates(offset=(self.last_update_id + 1),\n",
            "  File \"/usr/local/lib/python3.10/dist-packages/telebot/__init__.py\", line 648, in get_updates\n",
            "    json_updates = apihelper.get_updates(\n",
            "  File \"/usr/local/lib/python3.10/dist-packages/telebot/apihelper.py\", line 330, in get_updates\n",
            "    return _make_request(token, method_url, params=payload)\n",
            "  File \"/usr/local/lib/python3.10/dist-packages/telebot/apihelper.py\", line 168, in _make_request\n",
            "    json_result = _check_result(method_name, result)\n",
            "  File \"/usr/local/lib/python3.10/dist-packages/telebot/apihelper.py\", line 195, in _check_result\n",
            "    raise ApiTelegramException(method_name, result, result_json)\n",
            "telebot.apihelper.ApiTelegramException: A request to the Telegram API was unsuccessful. Error code: 409. Description: Conflict: terminated by other getUpdates request; make sure that only one bot instance is running\n",
            "\"\n",
            "ERROR:TeleBot:Exception traceback:\n",
            "Traceback (most recent call last):\n",
            "  File \"/usr/local/lib/python3.10/dist-packages/telebot/__init__.py\", line 1214, in __threaded_polling\n",
            "    polling_thread.raise_exceptions()\n",
            "  File \"/usr/local/lib/python3.10/dist-packages/telebot/util.py\", line 111, in raise_exceptions\n",
            "    raise self.exception_info\n",
            "  File \"/usr/local/lib/python3.10/dist-packages/telebot/util.py\", line 93, in run\n",
            "    task(*args, **kwargs)\n",
            "  File \"/usr/local/lib/python3.10/dist-packages/telebot/__init__.py\", line 676, in __retrieve_updates\n",
            "    updates = self.get_updates(offset=(self.last_update_id + 1),\n",
            "  File \"/usr/local/lib/python3.10/dist-packages/telebot/__init__.py\", line 648, in get_updates\n",
            "    json_updates = apihelper.get_updates(\n",
            "  File \"/usr/local/lib/python3.10/dist-packages/telebot/apihelper.py\", line 330, in get_updates\n",
            "    return _make_request(token, method_url, params=payload)\n",
            "  File \"/usr/local/lib/python3.10/dist-packages/telebot/apihelper.py\", line 168, in _make_request\n",
            "    json_result = _check_result(method_name, result)\n",
            "  File \"/usr/local/lib/python3.10/dist-packages/telebot/apihelper.py\", line 195, in _check_result\n",
            "    raise ApiTelegramException(method_name, result, result_json)\n",
            "telebot.apihelper.ApiTelegramException: A request to the Telegram API was unsuccessful. Error code: 409. Description: Conflict: terminated by other getUpdates request; make sure that only one bot instance is running\n",
            "\n",
            "2024-07-17 17:05:16,921 (__init__.py:1221 MainThread) ERROR - TeleBot: \"Threaded polling exception: A request to the Telegram API was unsuccessful. Error code: 409. Description: Conflict: terminated by other getUpdates request; make sure that only one bot instance is running\"\n",
            "ERROR:TeleBot:Threaded polling exception: A request to the Telegram API was unsuccessful. Error code: 409. Description: Conflict: terminated by other getUpdates request; make sure that only one bot instance is running\n",
            "2024-07-17 17:05:16,924 (__init__.py:1223 MainThread) ERROR - TeleBot: \"Exception traceback:\n",
            "Traceback (most recent call last):\n",
            "  File \"/usr/local/lib/python3.10/dist-packages/telebot/__init__.py\", line 1214, in __threaded_polling\n",
            "    polling_thread.raise_exceptions()\n",
            "  File \"/usr/local/lib/python3.10/dist-packages/telebot/util.py\", line 111, in raise_exceptions\n",
            "    raise self.exception_info\n",
            "  File \"/usr/local/lib/python3.10/dist-packages/telebot/util.py\", line 93, in run\n",
            "    task(*args, **kwargs)\n",
            "  File \"/usr/local/lib/python3.10/dist-packages/telebot/__init__.py\", line 676, in __retrieve_updates\n",
            "    updates = self.get_updates(offset=(self.last_update_id + 1),\n",
            "  File \"/usr/local/lib/python3.10/dist-packages/telebot/__init__.py\", line 648, in get_updates\n",
            "    json_updates = apihelper.get_updates(\n",
            "  File \"/usr/local/lib/python3.10/dist-packages/telebot/apihelper.py\", line 330, in get_updates\n",
            "    return _make_request(token, method_url, params=payload)\n",
            "  File \"/usr/local/lib/python3.10/dist-packages/telebot/apihelper.py\", line 168, in _make_request\n",
            "    json_result = _check_result(method_name, result)\n",
            "  File \"/usr/local/lib/python3.10/dist-packages/telebot/apihelper.py\", line 195, in _check_result\n",
            "    raise ApiTelegramException(method_name, result, result_json)\n",
            "telebot.apihelper.ApiTelegramException: A request to the Telegram API was unsuccessful. Error code: 409. Description: Conflict: terminated by other getUpdates request; make sure that only one bot instance is running\n",
            "\"\n",
            "ERROR:TeleBot:Exception traceback:\n",
            "Traceback (most recent call last):\n",
            "  File \"/usr/local/lib/python3.10/dist-packages/telebot/__init__.py\", line 1214, in __threaded_polling\n",
            "    polling_thread.raise_exceptions()\n",
            "  File \"/usr/local/lib/python3.10/dist-packages/telebot/util.py\", line 111, in raise_exceptions\n",
            "    raise self.exception_info\n",
            "  File \"/usr/local/lib/python3.10/dist-packages/telebot/util.py\", line 93, in run\n",
            "    task(*args, **kwargs)\n",
            "  File \"/usr/local/lib/python3.10/dist-packages/telebot/__init__.py\", line 676, in __retrieve_updates\n",
            "    updates = self.get_updates(offset=(self.last_update_id + 1),\n",
            "  File \"/usr/local/lib/python3.10/dist-packages/telebot/__init__.py\", line 648, in get_updates\n",
            "    json_updates = apihelper.get_updates(\n",
            "  File \"/usr/local/lib/python3.10/dist-packages/telebot/apihelper.py\", line 330, in get_updates\n",
            "    return _make_request(token, method_url, params=payload)\n",
            "  File \"/usr/local/lib/python3.10/dist-packages/telebot/apihelper.py\", line 168, in _make_request\n",
            "    json_result = _check_result(method_name, result)\n",
            "  File \"/usr/local/lib/python3.10/dist-packages/telebot/apihelper.py\", line 195, in _check_result\n",
            "    raise ApiTelegramException(method_name, result, result_json)\n",
            "telebot.apihelper.ApiTelegramException: A request to the Telegram API was unsuccessful. Error code: 409. Description: Conflict: terminated by other getUpdates request; make sure that only one bot instance is running\n",
            "\n",
            "2024-07-17 17:05:21,359 (__init__.py:1221 MainThread) ERROR - TeleBot: \"Threaded polling exception: A request to the Telegram API was unsuccessful. Error code: 409. Description: Conflict: terminated by other getUpdates request; make sure that only one bot instance is running\"\n",
            "ERROR:TeleBot:Threaded polling exception: A request to the Telegram API was unsuccessful. Error code: 409. Description: Conflict: terminated by other getUpdates request; make sure that only one bot instance is running\n",
            "2024-07-17 17:05:21,364 (__init__.py:1223 MainThread) ERROR - TeleBot: \"Exception traceback:\n",
            "Traceback (most recent call last):\n",
            "  File \"/usr/local/lib/python3.10/dist-packages/telebot/__init__.py\", line 1214, in __threaded_polling\n",
            "    polling_thread.raise_exceptions()\n",
            "  File \"/usr/local/lib/python3.10/dist-packages/telebot/util.py\", line 111, in raise_exceptions\n",
            "    raise self.exception_info\n",
            "  File \"/usr/local/lib/python3.10/dist-packages/telebot/util.py\", line 93, in run\n",
            "    task(*args, **kwargs)\n",
            "  File \"/usr/local/lib/python3.10/dist-packages/telebot/__init__.py\", line 676, in __retrieve_updates\n",
            "    updates = self.get_updates(offset=(self.last_update_id + 1),\n",
            "  File \"/usr/local/lib/python3.10/dist-packages/telebot/__init__.py\", line 648, in get_updates\n",
            "    json_updates = apihelper.get_updates(\n",
            "  File \"/usr/local/lib/python3.10/dist-packages/telebot/apihelper.py\", line 330, in get_updates\n",
            "    return _make_request(token, method_url, params=payload)\n",
            "  File \"/usr/local/lib/python3.10/dist-packages/telebot/apihelper.py\", line 168, in _make_request\n",
            "    json_result = _check_result(method_name, result)\n",
            "  File \"/usr/local/lib/python3.10/dist-packages/telebot/apihelper.py\", line 195, in _check_result\n",
            "    raise ApiTelegramException(method_name, result, result_json)\n",
            "telebot.apihelper.ApiTelegramException: A request to the Telegram API was unsuccessful. Error code: 409. Description: Conflict: terminated by other getUpdates request; make sure that only one bot instance is running\n",
            "\"\n",
            "ERROR:TeleBot:Exception traceback:\n",
            "Traceback (most recent call last):\n",
            "  File \"/usr/local/lib/python3.10/dist-packages/telebot/__init__.py\", line 1214, in __threaded_polling\n",
            "    polling_thread.raise_exceptions()\n",
            "  File \"/usr/local/lib/python3.10/dist-packages/telebot/util.py\", line 111, in raise_exceptions\n",
            "    raise self.exception_info\n",
            "  File \"/usr/local/lib/python3.10/dist-packages/telebot/util.py\", line 93, in run\n",
            "    task(*args, **kwargs)\n",
            "  File \"/usr/local/lib/python3.10/dist-packages/telebot/__init__.py\", line 676, in __retrieve_updates\n",
            "    updates = self.get_updates(offset=(self.last_update_id + 1),\n",
            "  File \"/usr/local/lib/python3.10/dist-packages/telebot/__init__.py\", line 648, in get_updates\n",
            "    json_updates = apihelper.get_updates(\n",
            "  File \"/usr/local/lib/python3.10/dist-packages/telebot/apihelper.py\", line 330, in get_updates\n",
            "    return _make_request(token, method_url, params=payload)\n",
            "  File \"/usr/local/lib/python3.10/dist-packages/telebot/apihelper.py\", line 168, in _make_request\n",
            "    json_result = _check_result(method_name, result)\n",
            "  File \"/usr/local/lib/python3.10/dist-packages/telebot/apihelper.py\", line 195, in _check_result\n",
            "    raise ApiTelegramException(method_name, result, result_json)\n",
            "telebot.apihelper.ApiTelegramException: A request to the Telegram API was unsuccessful. Error code: 409. Description: Conflict: terminated by other getUpdates request; make sure that only one bot instance is running\n",
            "\n",
            "2024-07-17 17:05:26,075 (__init__.py:1221 MainThread) ERROR - TeleBot: \"Threaded polling exception: A request to the Telegram API was unsuccessful. Error code: 409. Description: Conflict: terminated by other getUpdates request; make sure that only one bot instance is running\"\n",
            "ERROR:TeleBot:Threaded polling exception: A request to the Telegram API was unsuccessful. Error code: 409. Description: Conflict: terminated by other getUpdates request; make sure that only one bot instance is running\n",
            "2024-07-17 17:05:26,079 (__init__.py:1223 MainThread) ERROR - TeleBot: \"Exception traceback:\n",
            "Traceback (most recent call last):\n",
            "  File \"/usr/local/lib/python3.10/dist-packages/telebot/__init__.py\", line 1214, in __threaded_polling\n",
            "    polling_thread.raise_exceptions()\n",
            "  File \"/usr/local/lib/python3.10/dist-packages/telebot/util.py\", line 111, in raise_exceptions\n",
            "    raise self.exception_info\n",
            "  File \"/usr/local/lib/python3.10/dist-packages/telebot/util.py\", line 93, in run\n",
            "    task(*args, **kwargs)\n",
            "  File \"/usr/local/lib/python3.10/dist-packages/telebot/__init__.py\", line 676, in __retrieve_updates\n",
            "    updates = self.get_updates(offset=(self.last_update_id + 1),\n",
            "  File \"/usr/local/lib/python3.10/dist-packages/telebot/__init__.py\", line 648, in get_updates\n",
            "    json_updates = apihelper.get_updates(\n",
            "  File \"/usr/local/lib/python3.10/dist-packages/telebot/apihelper.py\", line 330, in get_updates\n",
            "    return _make_request(token, method_url, params=payload)\n",
            "  File \"/usr/local/lib/python3.10/dist-packages/telebot/apihelper.py\", line 168, in _make_request\n",
            "    json_result = _check_result(method_name, result)\n",
            "  File \"/usr/local/lib/python3.10/dist-packages/telebot/apihelper.py\", line 195, in _check_result\n",
            "    raise ApiTelegramException(method_name, result, result_json)\n",
            "telebot.apihelper.ApiTelegramException: A request to the Telegram API was unsuccessful. Error code: 409. Description: Conflict: terminated by other getUpdates request; make sure that only one bot instance is running\n",
            "\"\n",
            "ERROR:TeleBot:Exception traceback:\n",
            "Traceback (most recent call last):\n",
            "  File \"/usr/local/lib/python3.10/dist-packages/telebot/__init__.py\", line 1214, in __threaded_polling\n",
            "    polling_thread.raise_exceptions()\n",
            "  File \"/usr/local/lib/python3.10/dist-packages/telebot/util.py\", line 111, in raise_exceptions\n",
            "    raise self.exception_info\n",
            "  File \"/usr/local/lib/python3.10/dist-packages/telebot/util.py\", line 93, in run\n",
            "    task(*args, **kwargs)\n",
            "  File \"/usr/local/lib/python3.10/dist-packages/telebot/__init__.py\", line 676, in __retrieve_updates\n",
            "    updates = self.get_updates(offset=(self.last_update_id + 1),\n",
            "  File \"/usr/local/lib/python3.10/dist-packages/telebot/__init__.py\", line 648, in get_updates\n",
            "    json_updates = apihelper.get_updates(\n",
            "  File \"/usr/local/lib/python3.10/dist-packages/telebot/apihelper.py\", line 330, in get_updates\n",
            "    return _make_request(token, method_url, params=payload)\n",
            "  File \"/usr/local/lib/python3.10/dist-packages/telebot/apihelper.py\", line 168, in _make_request\n",
            "    json_result = _check_result(method_name, result)\n",
            "  File \"/usr/local/lib/python3.10/dist-packages/telebot/apihelper.py\", line 195, in _check_result\n",
            "    raise ApiTelegramException(method_name, result, result_json)\n",
            "telebot.apihelper.ApiTelegramException: A request to the Telegram API was unsuccessful. Error code: 409. Description: Conflict: terminated by other getUpdates request; make sure that only one bot instance is running\n",
            "\n",
            "2024-07-17 17:05:32,043 (__init__.py:1221 MainThread) ERROR - TeleBot: \"Threaded polling exception: A request to the Telegram API was unsuccessful. Error code: 409. Description: Conflict: terminated by other getUpdates request; make sure that only one bot instance is running\"\n",
            "ERROR:TeleBot:Threaded polling exception: A request to the Telegram API was unsuccessful. Error code: 409. Description: Conflict: terminated by other getUpdates request; make sure that only one bot instance is running\n",
            "2024-07-17 17:05:32,046 (__init__.py:1223 MainThread) ERROR - TeleBot: \"Exception traceback:\n",
            "Traceback (most recent call last):\n",
            "  File \"/usr/local/lib/python3.10/dist-packages/telebot/__init__.py\", line 1214, in __threaded_polling\n",
            "    polling_thread.raise_exceptions()\n",
            "  File \"/usr/local/lib/python3.10/dist-packages/telebot/util.py\", line 111, in raise_exceptions\n",
            "    raise self.exception_info\n",
            "  File \"/usr/local/lib/python3.10/dist-packages/telebot/util.py\", line 93, in run\n",
            "    task(*args, **kwargs)\n",
            "  File \"/usr/local/lib/python3.10/dist-packages/telebot/__init__.py\", line 676, in __retrieve_updates\n",
            "    updates = self.get_updates(offset=(self.last_update_id + 1),\n",
            "  File \"/usr/local/lib/python3.10/dist-packages/telebot/__init__.py\", line 648, in get_updates\n",
            "    json_updates = apihelper.get_updates(\n",
            "  File \"/usr/local/lib/python3.10/dist-packages/telebot/apihelper.py\", line 330, in get_updates\n",
            "    return _make_request(token, method_url, params=payload)\n",
            "  File \"/usr/local/lib/python3.10/dist-packages/telebot/apihelper.py\", line 168, in _make_request\n",
            "    json_result = _check_result(method_name, result)\n",
            "  File \"/usr/local/lib/python3.10/dist-packages/telebot/apihelper.py\", line 195, in _check_result\n",
            "    raise ApiTelegramException(method_name, result, result_json)\n",
            "telebot.apihelper.ApiTelegramException: A request to the Telegram API was unsuccessful. Error code: 409. Description: Conflict: terminated by other getUpdates request; make sure that only one bot instance is running\n",
            "\"\n",
            "ERROR:TeleBot:Exception traceback:\n",
            "Traceback (most recent call last):\n",
            "  File \"/usr/local/lib/python3.10/dist-packages/telebot/__init__.py\", line 1214, in __threaded_polling\n",
            "    polling_thread.raise_exceptions()\n",
            "  File \"/usr/local/lib/python3.10/dist-packages/telebot/util.py\", line 111, in raise_exceptions\n",
            "    raise self.exception_info\n",
            "  File \"/usr/local/lib/python3.10/dist-packages/telebot/util.py\", line 93, in run\n",
            "    task(*args, **kwargs)\n",
            "  File \"/usr/local/lib/python3.10/dist-packages/telebot/__init__.py\", line 676, in __retrieve_updates\n",
            "    updates = self.get_updates(offset=(self.last_update_id + 1),\n",
            "  File \"/usr/local/lib/python3.10/dist-packages/telebot/__init__.py\", line 648, in get_updates\n",
            "    json_updates = apihelper.get_updates(\n",
            "  File \"/usr/local/lib/python3.10/dist-packages/telebot/apihelper.py\", line 330, in get_updates\n",
            "    return _make_request(token, method_url, params=payload)\n",
            "  File \"/usr/local/lib/python3.10/dist-packages/telebot/apihelper.py\", line 168, in _make_request\n",
            "    json_result = _check_result(method_name, result)\n",
            "  File \"/usr/local/lib/python3.10/dist-packages/telebot/apihelper.py\", line 195, in _check_result\n",
            "    raise ApiTelegramException(method_name, result, result_json)\n",
            "telebot.apihelper.ApiTelegramException: A request to the Telegram API was unsuccessful. Error code: 409. Description: Conflict: terminated by other getUpdates request; make sure that only one bot instance is running\n",
            "\n",
            "2024-07-17 17:05:35,550 (__init__.py:1221 MainThread) ERROR - TeleBot: \"Threaded polling exception: A request to the Telegram API was unsuccessful. Error code: 409. Description: Conflict: terminated by other getUpdates request; make sure that only one bot instance is running\"\n",
            "ERROR:TeleBot:Threaded polling exception: A request to the Telegram API was unsuccessful. Error code: 409. Description: Conflict: terminated by other getUpdates request; make sure that only one bot instance is running\n",
            "2024-07-17 17:05:35,554 (__init__.py:1223 MainThread) ERROR - TeleBot: \"Exception traceback:\n",
            "Traceback (most recent call last):\n",
            "  File \"/usr/local/lib/python3.10/dist-packages/telebot/__init__.py\", line 1214, in __threaded_polling\n",
            "    polling_thread.raise_exceptions()\n",
            "  File \"/usr/local/lib/python3.10/dist-packages/telebot/util.py\", line 111, in raise_exceptions\n",
            "    raise self.exception_info\n",
            "  File \"/usr/local/lib/python3.10/dist-packages/telebot/util.py\", line 93, in run\n",
            "    task(*args, **kwargs)\n",
            "  File \"/usr/local/lib/python3.10/dist-packages/telebot/__init__.py\", line 676, in __retrieve_updates\n",
            "    updates = self.get_updates(offset=(self.last_update_id + 1),\n",
            "  File \"/usr/local/lib/python3.10/dist-packages/telebot/__init__.py\", line 648, in get_updates\n",
            "    json_updates = apihelper.get_updates(\n",
            "  File \"/usr/local/lib/python3.10/dist-packages/telebot/apihelper.py\", line 330, in get_updates\n",
            "    return _make_request(token, method_url, params=payload)\n",
            "  File \"/usr/local/lib/python3.10/dist-packages/telebot/apihelper.py\", line 168, in _make_request\n",
            "    json_result = _check_result(method_name, result)\n",
            "  File \"/usr/local/lib/python3.10/dist-packages/telebot/apihelper.py\", line 195, in _check_result\n",
            "    raise ApiTelegramException(method_name, result, result_json)\n",
            "telebot.apihelper.ApiTelegramException: A request to the Telegram API was unsuccessful. Error code: 409. Description: Conflict: terminated by other getUpdates request; make sure that only one bot instance is running\n",
            "\"\n",
            "ERROR:TeleBot:Exception traceback:\n",
            "Traceback (most recent call last):\n",
            "  File \"/usr/local/lib/python3.10/dist-packages/telebot/__init__.py\", line 1214, in __threaded_polling\n",
            "    polling_thread.raise_exceptions()\n",
            "  File \"/usr/local/lib/python3.10/dist-packages/telebot/util.py\", line 111, in raise_exceptions\n",
            "    raise self.exception_info\n",
            "  File \"/usr/local/lib/python3.10/dist-packages/telebot/util.py\", line 93, in run\n",
            "    task(*args, **kwargs)\n",
            "  File \"/usr/local/lib/python3.10/dist-packages/telebot/__init__.py\", line 676, in __retrieve_updates\n",
            "    updates = self.get_updates(offset=(self.last_update_id + 1),\n",
            "  File \"/usr/local/lib/python3.10/dist-packages/telebot/__init__.py\", line 648, in get_updates\n",
            "    json_updates = apihelper.get_updates(\n",
            "  File \"/usr/local/lib/python3.10/dist-packages/telebot/apihelper.py\", line 330, in get_updates\n",
            "    return _make_request(token, method_url, params=payload)\n",
            "  File \"/usr/local/lib/python3.10/dist-packages/telebot/apihelper.py\", line 168, in _make_request\n",
            "    json_result = _check_result(method_name, result)\n",
            "  File \"/usr/local/lib/python3.10/dist-packages/telebot/apihelper.py\", line 195, in _check_result\n",
            "    raise ApiTelegramException(method_name, result, result_json)\n",
            "telebot.apihelper.ApiTelegramException: A request to the Telegram API was unsuccessful. Error code: 409. Description: Conflict: terminated by other getUpdates request; make sure that only one bot instance is running\n",
            "\n",
            "2024-07-17 17:05:41,245 (__init__.py:1221 MainThread) ERROR - TeleBot: \"Threaded polling exception: A request to the Telegram API was unsuccessful. Error code: 409. Description: Conflict: terminated by other getUpdates request; make sure that only one bot instance is running\"\n",
            "ERROR:TeleBot:Threaded polling exception: A request to the Telegram API was unsuccessful. Error code: 409. Description: Conflict: terminated by other getUpdates request; make sure that only one bot instance is running\n",
            "2024-07-17 17:05:41,249 (__init__.py:1223 MainThread) ERROR - TeleBot: \"Exception traceback:\n",
            "Traceback (most recent call last):\n",
            "  File \"/usr/local/lib/python3.10/dist-packages/telebot/__init__.py\", line 1214, in __threaded_polling\n",
            "    polling_thread.raise_exceptions()\n",
            "  File \"/usr/local/lib/python3.10/dist-packages/telebot/util.py\", line 111, in raise_exceptions\n",
            "    raise self.exception_info\n",
            "  File \"/usr/local/lib/python3.10/dist-packages/telebot/util.py\", line 93, in run\n",
            "    task(*args, **kwargs)\n",
            "  File \"/usr/local/lib/python3.10/dist-packages/telebot/__init__.py\", line 676, in __retrieve_updates\n",
            "    updates = self.get_updates(offset=(self.last_update_id + 1),\n",
            "  File \"/usr/local/lib/python3.10/dist-packages/telebot/__init__.py\", line 648, in get_updates\n",
            "    json_updates = apihelper.get_updates(\n",
            "  File \"/usr/local/lib/python3.10/dist-packages/telebot/apihelper.py\", line 330, in get_updates\n",
            "    return _make_request(token, method_url, params=payload)\n",
            "  File \"/usr/local/lib/python3.10/dist-packages/telebot/apihelper.py\", line 168, in _make_request\n",
            "    json_result = _check_result(method_name, result)\n",
            "  File \"/usr/local/lib/python3.10/dist-packages/telebot/apihelper.py\", line 195, in _check_result\n",
            "    raise ApiTelegramException(method_name, result, result_json)\n",
            "telebot.apihelper.ApiTelegramException: A request to the Telegram API was unsuccessful. Error code: 409. Description: Conflict: terminated by other getUpdates request; make sure that only one bot instance is running\n",
            "\"\n",
            "ERROR:TeleBot:Exception traceback:\n",
            "Traceback (most recent call last):\n",
            "  File \"/usr/local/lib/python3.10/dist-packages/telebot/__init__.py\", line 1214, in __threaded_polling\n",
            "    polling_thread.raise_exceptions()\n",
            "  File \"/usr/local/lib/python3.10/dist-packages/telebot/util.py\", line 111, in raise_exceptions\n",
            "    raise self.exception_info\n",
            "  File \"/usr/local/lib/python3.10/dist-packages/telebot/util.py\", line 93, in run\n",
            "    task(*args, **kwargs)\n",
            "  File \"/usr/local/lib/python3.10/dist-packages/telebot/__init__.py\", line 676, in __retrieve_updates\n",
            "    updates = self.get_updates(offset=(self.last_update_id + 1),\n",
            "  File \"/usr/local/lib/python3.10/dist-packages/telebot/__init__.py\", line 648, in get_updates\n",
            "    json_updates = apihelper.get_updates(\n",
            "  File \"/usr/local/lib/python3.10/dist-packages/telebot/apihelper.py\", line 330, in get_updates\n",
            "    return _make_request(token, method_url, params=payload)\n",
            "  File \"/usr/local/lib/python3.10/dist-packages/telebot/apihelper.py\", line 168, in _make_request\n",
            "    json_result = _check_result(method_name, result)\n",
            "  File \"/usr/local/lib/python3.10/dist-packages/telebot/apihelper.py\", line 195, in _check_result\n",
            "    raise ApiTelegramException(method_name, result, result_json)\n",
            "telebot.apihelper.ApiTelegramException: A request to the Telegram API was unsuccessful. Error code: 409. Description: Conflict: terminated by other getUpdates request; make sure that only one bot instance is running\n",
            "\n",
            "2024-07-17 17:05:49,194 (__init__.py:1221 MainThread) ERROR - TeleBot: \"Threaded polling exception: A request to the Telegram API was unsuccessful. Error code: 409. Description: Conflict: terminated by other getUpdates request; make sure that only one bot instance is running\"\n",
            "ERROR:TeleBot:Threaded polling exception: A request to the Telegram API was unsuccessful. Error code: 409. Description: Conflict: terminated by other getUpdates request; make sure that only one bot instance is running\n",
            "2024-07-17 17:05:49,199 (__init__.py:1223 MainThread) ERROR - TeleBot: \"Exception traceback:\n",
            "Traceback (most recent call last):\n",
            "  File \"/usr/local/lib/python3.10/dist-packages/telebot/__init__.py\", line 1214, in __threaded_polling\n",
            "    polling_thread.raise_exceptions()\n",
            "  File \"/usr/local/lib/python3.10/dist-packages/telebot/util.py\", line 111, in raise_exceptions\n",
            "    raise self.exception_info\n",
            "  File \"/usr/local/lib/python3.10/dist-packages/telebot/util.py\", line 93, in run\n",
            "    task(*args, **kwargs)\n",
            "  File \"/usr/local/lib/python3.10/dist-packages/telebot/__init__.py\", line 676, in __retrieve_updates\n",
            "    updates = self.get_updates(offset=(self.last_update_id + 1),\n",
            "  File \"/usr/local/lib/python3.10/dist-packages/telebot/__init__.py\", line 648, in get_updates\n",
            "    json_updates = apihelper.get_updates(\n",
            "  File \"/usr/local/lib/python3.10/dist-packages/telebot/apihelper.py\", line 330, in get_updates\n",
            "    return _make_request(token, method_url, params=payload)\n",
            "  File \"/usr/local/lib/python3.10/dist-packages/telebot/apihelper.py\", line 168, in _make_request\n",
            "    json_result = _check_result(method_name, result)\n",
            "  File \"/usr/local/lib/python3.10/dist-packages/telebot/apihelper.py\", line 195, in _check_result\n",
            "    raise ApiTelegramException(method_name, result, result_json)\n",
            "telebot.apihelper.ApiTelegramException: A request to the Telegram API was unsuccessful. Error code: 409. Description: Conflict: terminated by other getUpdates request; make sure that only one bot instance is running\n",
            "\"\n",
            "ERROR:TeleBot:Exception traceback:\n",
            "Traceback (most recent call last):\n",
            "  File \"/usr/local/lib/python3.10/dist-packages/telebot/__init__.py\", line 1214, in __threaded_polling\n",
            "    polling_thread.raise_exceptions()\n",
            "  File \"/usr/local/lib/python3.10/dist-packages/telebot/util.py\", line 111, in raise_exceptions\n",
            "    raise self.exception_info\n",
            "  File \"/usr/local/lib/python3.10/dist-packages/telebot/util.py\", line 93, in run\n",
            "    task(*args, **kwargs)\n",
            "  File \"/usr/local/lib/python3.10/dist-packages/telebot/__init__.py\", line 676, in __retrieve_updates\n",
            "    updates = self.get_updates(offset=(self.last_update_id + 1),\n",
            "  File \"/usr/local/lib/python3.10/dist-packages/telebot/__init__.py\", line 648, in get_updates\n",
            "    json_updates = apihelper.get_updates(\n",
            "  File \"/usr/local/lib/python3.10/dist-packages/telebot/apihelper.py\", line 330, in get_updates\n",
            "    return _make_request(token, method_url, params=payload)\n",
            "  File \"/usr/local/lib/python3.10/dist-packages/telebot/apihelper.py\", line 168, in _make_request\n",
            "    json_result = _check_result(method_name, result)\n",
            "  File \"/usr/local/lib/python3.10/dist-packages/telebot/apihelper.py\", line 195, in _check_result\n",
            "    raise ApiTelegramException(method_name, result, result_json)\n",
            "telebot.apihelper.ApiTelegramException: A request to the Telegram API was unsuccessful. Error code: 409. Description: Conflict: terminated by other getUpdates request; make sure that only one bot instance is running\n",
            "\n",
            "2024-07-17 17:06:01,650 (__init__.py:1221 MainThread) ERROR - TeleBot: \"Threaded polling exception: A request to the Telegram API was unsuccessful. Error code: 409. Description: Conflict: terminated by other getUpdates request; make sure that only one bot instance is running\"\n",
            "ERROR:TeleBot:Threaded polling exception: A request to the Telegram API was unsuccessful. Error code: 409. Description: Conflict: terminated by other getUpdates request; make sure that only one bot instance is running\n",
            "2024-07-17 17:06:01,653 (__init__.py:1223 MainThread) ERROR - TeleBot: \"Exception traceback:\n",
            "Traceback (most recent call last):\n",
            "  File \"/usr/local/lib/python3.10/dist-packages/telebot/__init__.py\", line 1214, in __threaded_polling\n",
            "    polling_thread.raise_exceptions()\n",
            "  File \"/usr/local/lib/python3.10/dist-packages/telebot/util.py\", line 111, in raise_exceptions\n",
            "    raise self.exception_info\n",
            "  File \"/usr/local/lib/python3.10/dist-packages/telebot/util.py\", line 93, in run\n",
            "    task(*args, **kwargs)\n",
            "  File \"/usr/local/lib/python3.10/dist-packages/telebot/__init__.py\", line 676, in __retrieve_updates\n",
            "    updates = self.get_updates(offset=(self.last_update_id + 1),\n",
            "  File \"/usr/local/lib/python3.10/dist-packages/telebot/__init__.py\", line 648, in get_updates\n",
            "    json_updates = apihelper.get_updates(\n",
            "  File \"/usr/local/lib/python3.10/dist-packages/telebot/apihelper.py\", line 330, in get_updates\n",
            "    return _make_request(token, method_url, params=payload)\n",
            "  File \"/usr/local/lib/python3.10/dist-packages/telebot/apihelper.py\", line 168, in _make_request\n",
            "    json_result = _check_result(method_name, result)\n",
            "  File \"/usr/local/lib/python3.10/dist-packages/telebot/apihelper.py\", line 195, in _check_result\n",
            "    raise ApiTelegramException(method_name, result, result_json)\n",
            "telebot.apihelper.ApiTelegramException: A request to the Telegram API was unsuccessful. Error code: 409. Description: Conflict: terminated by other getUpdates request; make sure that only one bot instance is running\n",
            "\"\n",
            "ERROR:TeleBot:Exception traceback:\n",
            "Traceback (most recent call last):\n",
            "  File \"/usr/local/lib/python3.10/dist-packages/telebot/__init__.py\", line 1214, in __threaded_polling\n",
            "    polling_thread.raise_exceptions()\n",
            "  File \"/usr/local/lib/python3.10/dist-packages/telebot/util.py\", line 111, in raise_exceptions\n",
            "    raise self.exception_info\n",
            "  File \"/usr/local/lib/python3.10/dist-packages/telebot/util.py\", line 93, in run\n",
            "    task(*args, **kwargs)\n",
            "  File \"/usr/local/lib/python3.10/dist-packages/telebot/__init__.py\", line 676, in __retrieve_updates\n",
            "    updates = self.get_updates(offset=(self.last_update_id + 1),\n",
            "  File \"/usr/local/lib/python3.10/dist-packages/telebot/__init__.py\", line 648, in get_updates\n",
            "    json_updates = apihelper.get_updates(\n",
            "  File \"/usr/local/lib/python3.10/dist-packages/telebot/apihelper.py\", line 330, in get_updates\n",
            "    return _make_request(token, method_url, params=payload)\n",
            "  File \"/usr/local/lib/python3.10/dist-packages/telebot/apihelper.py\", line 168, in _make_request\n",
            "    json_result = _check_result(method_name, result)\n",
            "  File \"/usr/local/lib/python3.10/dist-packages/telebot/apihelper.py\", line 195, in _check_result\n",
            "    raise ApiTelegramException(method_name, result, result_json)\n",
            "telebot.apihelper.ApiTelegramException: A request to the Telegram API was unsuccessful. Error code: 409. Description: Conflict: terminated by other getUpdates request; make sure that only one bot instance is running\n",
            "\n",
            "2024-07-17 17:06:23,110 (__init__.py:1221 MainThread) ERROR - TeleBot: \"Threaded polling exception: A request to the Telegram API was unsuccessful. Error code: 409. Description: Conflict: terminated by other getUpdates request; make sure that only one bot instance is running\"\n",
            "ERROR:TeleBot:Threaded polling exception: A request to the Telegram API was unsuccessful. Error code: 409. Description: Conflict: terminated by other getUpdates request; make sure that only one bot instance is running\n",
            "2024-07-17 17:06:23,113 (__init__.py:1223 MainThread) ERROR - TeleBot: \"Exception traceback:\n",
            "Traceback (most recent call last):\n",
            "  File \"/usr/local/lib/python3.10/dist-packages/telebot/__init__.py\", line 1214, in __threaded_polling\n",
            "    polling_thread.raise_exceptions()\n",
            "  File \"/usr/local/lib/python3.10/dist-packages/telebot/util.py\", line 111, in raise_exceptions\n",
            "    raise self.exception_info\n",
            "  File \"/usr/local/lib/python3.10/dist-packages/telebot/util.py\", line 93, in run\n",
            "    task(*args, **kwargs)\n",
            "  File \"/usr/local/lib/python3.10/dist-packages/telebot/__init__.py\", line 676, in __retrieve_updates\n",
            "    updates = self.get_updates(offset=(self.last_update_id + 1),\n",
            "  File \"/usr/local/lib/python3.10/dist-packages/telebot/__init__.py\", line 648, in get_updates\n",
            "    json_updates = apihelper.get_updates(\n",
            "  File \"/usr/local/lib/python3.10/dist-packages/telebot/apihelper.py\", line 330, in get_updates\n",
            "    return _make_request(token, method_url, params=payload)\n",
            "  File \"/usr/local/lib/python3.10/dist-packages/telebot/apihelper.py\", line 168, in _make_request\n",
            "    json_result = _check_result(method_name, result)\n",
            "  File \"/usr/local/lib/python3.10/dist-packages/telebot/apihelper.py\", line 195, in _check_result\n",
            "    raise ApiTelegramException(method_name, result, result_json)\n",
            "telebot.apihelper.ApiTelegramException: A request to the Telegram API was unsuccessful. Error code: 409. Description: Conflict: terminated by other getUpdates request; make sure that only one bot instance is running\n",
            "\"\n",
            "ERROR:TeleBot:Exception traceback:\n",
            "Traceback (most recent call last):\n",
            "  File \"/usr/local/lib/python3.10/dist-packages/telebot/__init__.py\", line 1214, in __threaded_polling\n",
            "    polling_thread.raise_exceptions()\n",
            "  File \"/usr/local/lib/python3.10/dist-packages/telebot/util.py\", line 111, in raise_exceptions\n",
            "    raise self.exception_info\n",
            "  File \"/usr/local/lib/python3.10/dist-packages/telebot/util.py\", line 93, in run\n",
            "    task(*args, **kwargs)\n",
            "  File \"/usr/local/lib/python3.10/dist-packages/telebot/__init__.py\", line 676, in __retrieve_updates\n",
            "    updates = self.get_updates(offset=(self.last_update_id + 1),\n",
            "  File \"/usr/local/lib/python3.10/dist-packages/telebot/__init__.py\", line 648, in get_updates\n",
            "    json_updates = apihelper.get_updates(\n",
            "  File \"/usr/local/lib/python3.10/dist-packages/telebot/apihelper.py\", line 330, in get_updates\n",
            "    return _make_request(token, method_url, params=payload)\n",
            "  File \"/usr/local/lib/python3.10/dist-packages/telebot/apihelper.py\", line 168, in _make_request\n",
            "    json_result = _check_result(method_name, result)\n",
            "  File \"/usr/local/lib/python3.10/dist-packages/telebot/apihelper.py\", line 195, in _check_result\n",
            "    raise ApiTelegramException(method_name, result, result_json)\n",
            "telebot.apihelper.ApiTelegramException: A request to the Telegram API was unsuccessful. Error code: 409. Description: Conflict: terminated by other getUpdates request; make sure that only one bot instance is running\n",
            "\n",
            "2024-07-17 17:06:58,832 (__init__.py:1221 MainThread) ERROR - TeleBot: \"Threaded polling exception: A request to the Telegram API was unsuccessful. Error code: 409. Description: Conflict: terminated by other getUpdates request; make sure that only one bot instance is running\"\n",
            "ERROR:TeleBot:Threaded polling exception: A request to the Telegram API was unsuccessful. Error code: 409. Description: Conflict: terminated by other getUpdates request; make sure that only one bot instance is running\n",
            "2024-07-17 17:06:58,835 (__init__.py:1223 MainThread) ERROR - TeleBot: \"Exception traceback:\n",
            "Traceback (most recent call last):\n",
            "  File \"/usr/local/lib/python3.10/dist-packages/telebot/__init__.py\", line 1214, in __threaded_polling\n",
            "    polling_thread.raise_exceptions()\n",
            "  File \"/usr/local/lib/python3.10/dist-packages/telebot/util.py\", line 111, in raise_exceptions\n",
            "    raise self.exception_info\n",
            "  File \"/usr/local/lib/python3.10/dist-packages/telebot/util.py\", line 93, in run\n",
            "    task(*args, **kwargs)\n",
            "  File \"/usr/local/lib/python3.10/dist-packages/telebot/__init__.py\", line 676, in __retrieve_updates\n",
            "    updates = self.get_updates(offset=(self.last_update_id + 1),\n",
            "  File \"/usr/local/lib/python3.10/dist-packages/telebot/__init__.py\", line 648, in get_updates\n",
            "    json_updates = apihelper.get_updates(\n",
            "  File \"/usr/local/lib/python3.10/dist-packages/telebot/apihelper.py\", line 330, in get_updates\n",
            "    return _make_request(token, method_url, params=payload)\n",
            "  File \"/usr/local/lib/python3.10/dist-packages/telebot/apihelper.py\", line 168, in _make_request\n",
            "    json_result = _check_result(method_name, result)\n",
            "  File \"/usr/local/lib/python3.10/dist-packages/telebot/apihelper.py\", line 195, in _check_result\n",
            "    raise ApiTelegramException(method_name, result, result_json)\n",
            "telebot.apihelper.ApiTelegramException: A request to the Telegram API was unsuccessful. Error code: 409. Description: Conflict: terminated by other getUpdates request; make sure that only one bot instance is running\n",
            "\"\n",
            "ERROR:TeleBot:Exception traceback:\n",
            "Traceback (most recent call last):\n",
            "  File \"/usr/local/lib/python3.10/dist-packages/telebot/__init__.py\", line 1214, in __threaded_polling\n",
            "    polling_thread.raise_exceptions()\n",
            "  File \"/usr/local/lib/python3.10/dist-packages/telebot/util.py\", line 111, in raise_exceptions\n",
            "    raise self.exception_info\n",
            "  File \"/usr/local/lib/python3.10/dist-packages/telebot/util.py\", line 93, in run\n",
            "    task(*args, **kwargs)\n",
            "  File \"/usr/local/lib/python3.10/dist-packages/telebot/__init__.py\", line 676, in __retrieve_updates\n",
            "    updates = self.get_updates(offset=(self.last_update_id + 1),\n",
            "  File \"/usr/local/lib/python3.10/dist-packages/telebot/__init__.py\", line 648, in get_updates\n",
            "    json_updates = apihelper.get_updates(\n",
            "  File \"/usr/local/lib/python3.10/dist-packages/telebot/apihelper.py\", line 330, in get_updates\n",
            "    return _make_request(token, method_url, params=payload)\n",
            "  File \"/usr/local/lib/python3.10/dist-packages/telebot/apihelper.py\", line 168, in _make_request\n",
            "    json_result = _check_result(method_name, result)\n",
            "  File \"/usr/local/lib/python3.10/dist-packages/telebot/apihelper.py\", line 195, in _check_result\n",
            "    raise ApiTelegramException(method_name, result, result_json)\n",
            "telebot.apihelper.ApiTelegramException: A request to the Telegram API was unsuccessful. Error code: 409. Description: Conflict: terminated by other getUpdates request; make sure that only one bot instance is running\n",
            "\n",
            "2024-07-17 17:08:02,555 (__init__.py:1221 MainThread) ERROR - TeleBot: \"Threaded polling exception: A request to the Telegram API was unsuccessful. Error code: 409. Description: Conflict: terminated by other getUpdates request; make sure that only one bot instance is running\"\n",
            "ERROR:TeleBot:Threaded polling exception: A request to the Telegram API was unsuccessful. Error code: 409. Description: Conflict: terminated by other getUpdates request; make sure that only one bot instance is running\n",
            "2024-07-17 17:08:02,559 (__init__.py:1223 MainThread) ERROR - TeleBot: \"Exception traceback:\n",
            "Traceback (most recent call last):\n",
            "  File \"/usr/local/lib/python3.10/dist-packages/telebot/__init__.py\", line 1214, in __threaded_polling\n",
            "    polling_thread.raise_exceptions()\n",
            "  File \"/usr/local/lib/python3.10/dist-packages/telebot/util.py\", line 111, in raise_exceptions\n",
            "    raise self.exception_info\n",
            "  File \"/usr/local/lib/python3.10/dist-packages/telebot/util.py\", line 93, in run\n",
            "    task(*args, **kwargs)\n",
            "  File \"/usr/local/lib/python3.10/dist-packages/telebot/__init__.py\", line 676, in __retrieve_updates\n",
            "    updates = self.get_updates(offset=(self.last_update_id + 1),\n",
            "  File \"/usr/local/lib/python3.10/dist-packages/telebot/__init__.py\", line 648, in get_updates\n",
            "    json_updates = apihelper.get_updates(\n",
            "  File \"/usr/local/lib/python3.10/dist-packages/telebot/apihelper.py\", line 330, in get_updates\n",
            "    return _make_request(token, method_url, params=payload)\n",
            "  File \"/usr/local/lib/python3.10/dist-packages/telebot/apihelper.py\", line 168, in _make_request\n",
            "    json_result = _check_result(method_name, result)\n",
            "  File \"/usr/local/lib/python3.10/dist-packages/telebot/apihelper.py\", line 195, in _check_result\n",
            "    raise ApiTelegramException(method_name, result, result_json)\n",
            "telebot.apihelper.ApiTelegramException: A request to the Telegram API was unsuccessful. Error code: 409. Description: Conflict: terminated by other getUpdates request; make sure that only one bot instance is running\n",
            "\"\n",
            "ERROR:TeleBot:Exception traceback:\n",
            "Traceback (most recent call last):\n",
            "  File \"/usr/local/lib/python3.10/dist-packages/telebot/__init__.py\", line 1214, in __threaded_polling\n",
            "    polling_thread.raise_exceptions()\n",
            "  File \"/usr/local/lib/python3.10/dist-packages/telebot/util.py\", line 111, in raise_exceptions\n",
            "    raise self.exception_info\n",
            "  File \"/usr/local/lib/python3.10/dist-packages/telebot/util.py\", line 93, in run\n",
            "    task(*args, **kwargs)\n",
            "  File \"/usr/local/lib/python3.10/dist-packages/telebot/__init__.py\", line 676, in __retrieve_updates\n",
            "    updates = self.get_updates(offset=(self.last_update_id + 1),\n",
            "  File \"/usr/local/lib/python3.10/dist-packages/telebot/__init__.py\", line 648, in get_updates\n",
            "    json_updates = apihelper.get_updates(\n",
            "  File \"/usr/local/lib/python3.10/dist-packages/telebot/apihelper.py\", line 330, in get_updates\n",
            "    return _make_request(token, method_url, params=payload)\n",
            "  File \"/usr/local/lib/python3.10/dist-packages/telebot/apihelper.py\", line 168, in _make_request\n",
            "    json_result = _check_result(method_name, result)\n",
            "  File \"/usr/local/lib/python3.10/dist-packages/telebot/apihelper.py\", line 195, in _check_result\n",
            "    raise ApiTelegramException(method_name, result, result_json)\n",
            "telebot.apihelper.ApiTelegramException: A request to the Telegram API was unsuccessful. Error code: 409. Description: Conflict: terminated by other getUpdates request; make sure that only one bot instance is running\n",
            "\n"
          ]
        },
        {
          "output_type": "error",
          "ename": "KeyboardInterrupt",
          "evalue": "",
          "traceback": [
            "\u001b[0;31m---------------------------------------------------------------------------\u001b[0m",
            "\u001b[0;31mApiTelegramException\u001b[0m                      Traceback (most recent call last)",
            "\u001b[0;32m/usr/local/lib/python3.10/dist-packages/telebot/__init__.py\u001b[0m in \u001b[0;36m__threaded_polling\u001b[0;34m(self, non_stop, interval, timeout, long_polling_timeout, logger_level, allowed_updates)\u001b[0m\n\u001b[1;32m   1213\u001b[0m                 \u001b[0mor_event\u001b[0m\u001b[0;34m.\u001b[0m\u001b[0mwait\u001b[0m\u001b[0;34m(\u001b[0m\u001b[0;34m)\u001b[0m  \u001b[0;31m# wait for polling thread finish, polling thread error or thread pool error\u001b[0m\u001b[0;34m\u001b[0m\u001b[0;34m\u001b[0m\u001b[0m\n\u001b[0;32m-> 1214\u001b[0;31m                 \u001b[0mpolling_thread\u001b[0m\u001b[0;34m.\u001b[0m\u001b[0mraise_exceptions\u001b[0m\u001b[0;34m(\u001b[0m\u001b[0;34m)\u001b[0m\u001b[0;34m\u001b[0m\u001b[0;34m\u001b[0m\u001b[0m\n\u001b[0m\u001b[1;32m   1215\u001b[0m                 \u001b[0mself\u001b[0m\u001b[0;34m.\u001b[0m\u001b[0mworker_pool\u001b[0m\u001b[0;34m.\u001b[0m\u001b[0mraise_exceptions\u001b[0m\u001b[0;34m(\u001b[0m\u001b[0;34m)\u001b[0m\u001b[0;34m\u001b[0m\u001b[0;34m\u001b[0m\u001b[0m\n",
            "\u001b[0;32m/usr/local/lib/python3.10/dist-packages/telebot/util.py\u001b[0m in \u001b[0;36mraise_exceptions\u001b[0;34m(self)\u001b[0m\n\u001b[1;32m    110\u001b[0m         \u001b[0;32mif\u001b[0m \u001b[0mself\u001b[0m\u001b[0;34m.\u001b[0m\u001b[0mexception_event\u001b[0m\u001b[0;34m.\u001b[0m\u001b[0mis_set\u001b[0m\u001b[0;34m(\u001b[0m\u001b[0;34m)\u001b[0m\u001b[0;34m:\u001b[0m\u001b[0;34m\u001b[0m\u001b[0;34m\u001b[0m\u001b[0m\n\u001b[0;32m--> 111\u001b[0;31m             \u001b[0;32mraise\u001b[0m \u001b[0mself\u001b[0m\u001b[0;34m.\u001b[0m\u001b[0mexception_info\u001b[0m\u001b[0;34m\u001b[0m\u001b[0;34m\u001b[0m\u001b[0m\n\u001b[0m\u001b[1;32m    112\u001b[0m \u001b[0;34m\u001b[0m\u001b[0m\n",
            "\u001b[0;32m/usr/local/lib/python3.10/dist-packages/telebot/util.py\u001b[0m in \u001b[0;36mrun\u001b[0;34m(self)\u001b[0m\n\u001b[1;32m     92\u001b[0m \u001b[0;34m\u001b[0m\u001b[0m\n\u001b[0;32m---> 93\u001b[0;31m                 \u001b[0mtask\u001b[0m\u001b[0;34m(\u001b[0m\u001b[0;34m*\u001b[0m\u001b[0margs\u001b[0m\u001b[0;34m,\u001b[0m \u001b[0;34m**\u001b[0m\u001b[0mkwargs\u001b[0m\u001b[0;34m)\u001b[0m\u001b[0;34m\u001b[0m\u001b[0;34m\u001b[0m\u001b[0m\n\u001b[0m\u001b[1;32m     94\u001b[0m                 \u001b[0mlogger\u001b[0m\u001b[0;34m.\u001b[0m\u001b[0mdebug\u001b[0m\u001b[0;34m(\u001b[0m\u001b[0;34m\"Task complete\"\u001b[0m\u001b[0;34m)\u001b[0m\u001b[0;34m\u001b[0m\u001b[0;34m\u001b[0m\u001b[0m\n",
            "\u001b[0;32m/usr/local/lib/python3.10/dist-packages/telebot/__init__.py\u001b[0m in \u001b[0;36m__retrieve_updates\u001b[0;34m(self, timeout, long_polling_timeout, allowed_updates)\u001b[0m\n\u001b[1;32m    675\u001b[0m             \u001b[0mself\u001b[0m\u001b[0;34m.\u001b[0m\u001b[0mskip_pending\u001b[0m \u001b[0;34m=\u001b[0m \u001b[0;32mFalse\u001b[0m\u001b[0;34m\u001b[0m\u001b[0;34m\u001b[0m\u001b[0m\n\u001b[0;32m--> 676\u001b[0;31m         updates = self.get_updates(offset=(self.last_update_id + 1), \n\u001b[0m\u001b[1;32m    677\u001b[0m                                    \u001b[0mallowed_updates\u001b[0m\u001b[0;34m=\u001b[0m\u001b[0mallowed_updates\u001b[0m\u001b[0;34m,\u001b[0m\u001b[0;34m\u001b[0m\u001b[0;34m\u001b[0m\u001b[0m\n",
            "\u001b[0;32m/usr/local/lib/python3.10/dist-packages/telebot/__init__.py\u001b[0m in \u001b[0;36mget_updates\u001b[0;34m(self, offset, limit, timeout, allowed_updates, long_polling_timeout)\u001b[0m\n\u001b[1;32m    647\u001b[0m         \"\"\"\n\u001b[0;32m--> 648\u001b[0;31m         json_updates = apihelper.get_updates(\n\u001b[0m\u001b[1;32m    649\u001b[0m             \u001b[0mself\u001b[0m\u001b[0;34m.\u001b[0m\u001b[0mtoken\u001b[0m\u001b[0;34m,\u001b[0m \u001b[0moffset\u001b[0m\u001b[0;34m=\u001b[0m\u001b[0moffset\u001b[0m\u001b[0;34m,\u001b[0m \u001b[0mlimit\u001b[0m\u001b[0;34m=\u001b[0m\u001b[0mlimit\u001b[0m\u001b[0;34m,\u001b[0m \u001b[0mtimeout\u001b[0m\u001b[0;34m=\u001b[0m\u001b[0mtimeout\u001b[0m\u001b[0;34m,\u001b[0m \u001b[0mallowed_updates\u001b[0m\u001b[0;34m=\u001b[0m\u001b[0mallowed_updates\u001b[0m\u001b[0;34m,\u001b[0m\u001b[0;34m\u001b[0m\u001b[0;34m\u001b[0m\u001b[0m\n",
            "\u001b[0;32m/usr/local/lib/python3.10/dist-packages/telebot/apihelper.py\u001b[0m in \u001b[0;36mget_updates\u001b[0;34m(token, offset, limit, timeout, allowed_updates, long_polling_timeout)\u001b[0m\n\u001b[1;32m    329\u001b[0m         \u001b[0mpayload\u001b[0m\u001b[0;34m[\u001b[0m\u001b[0;34m'allowed_updates'\u001b[0m\u001b[0;34m]\u001b[0m \u001b[0;34m=\u001b[0m \u001b[0mjson\u001b[0m\u001b[0;34m.\u001b[0m\u001b[0mdumps\u001b[0m\u001b[0;34m(\u001b[0m\u001b[0mallowed_updates\u001b[0m\u001b[0;34m)\u001b[0m\u001b[0;34m\u001b[0m\u001b[0;34m\u001b[0m\u001b[0m\n\u001b[0;32m--> 330\u001b[0;31m     \u001b[0;32mreturn\u001b[0m \u001b[0m_make_request\u001b[0m\u001b[0;34m(\u001b[0m\u001b[0mtoken\u001b[0m\u001b[0;34m,\u001b[0m \u001b[0mmethod_url\u001b[0m\u001b[0;34m,\u001b[0m \u001b[0mparams\u001b[0m\u001b[0;34m=\u001b[0m\u001b[0mpayload\u001b[0m\u001b[0;34m)\u001b[0m\u001b[0;34m\u001b[0m\u001b[0;34m\u001b[0m\u001b[0m\n\u001b[0m\u001b[1;32m    331\u001b[0m \u001b[0;34m\u001b[0m\u001b[0m\n",
            "\u001b[0;32m/usr/local/lib/python3.10/dist-packages/telebot/apihelper.py\u001b[0m in \u001b[0;36m_make_request\u001b[0;34m(token, method_name, method, params, files)\u001b[0m\n\u001b[1;32m    167\u001b[0m \u001b[0;34m\u001b[0m\u001b[0m\n\u001b[0;32m--> 168\u001b[0;31m     \u001b[0mjson_result\u001b[0m \u001b[0;34m=\u001b[0m \u001b[0m_check_result\u001b[0m\u001b[0;34m(\u001b[0m\u001b[0mmethod_name\u001b[0m\u001b[0;34m,\u001b[0m \u001b[0mresult\u001b[0m\u001b[0;34m)\u001b[0m\u001b[0;34m\u001b[0m\u001b[0;34m\u001b[0m\u001b[0m\n\u001b[0m\u001b[1;32m    169\u001b[0m     \u001b[0;32mif\u001b[0m \u001b[0mjson_result\u001b[0m\u001b[0;34m:\u001b[0m\u001b[0;34m\u001b[0m\u001b[0;34m\u001b[0m\u001b[0m\n",
            "\u001b[0;32m/usr/local/lib/python3.10/dist-packages/telebot/apihelper.py\u001b[0m in \u001b[0;36m_check_result\u001b[0;34m(method_name, result)\u001b[0m\n\u001b[1;32m    194\u001b[0m         \u001b[0;32mif\u001b[0m \u001b[0;32mnot\u001b[0m \u001b[0mresult_json\u001b[0m\u001b[0;34m[\u001b[0m\u001b[0;34m'ok'\u001b[0m\u001b[0;34m]\u001b[0m\u001b[0;34m:\u001b[0m\u001b[0;34m\u001b[0m\u001b[0;34m\u001b[0m\u001b[0m\n\u001b[0;32m--> 195\u001b[0;31m             \u001b[0;32mraise\u001b[0m \u001b[0mApiTelegramException\u001b[0m\u001b[0;34m(\u001b[0m\u001b[0mmethod_name\u001b[0m\u001b[0;34m,\u001b[0m \u001b[0mresult\u001b[0m\u001b[0;34m,\u001b[0m \u001b[0mresult_json\u001b[0m\u001b[0;34m)\u001b[0m\u001b[0;34m\u001b[0m\u001b[0;34m\u001b[0m\u001b[0m\n\u001b[0m\u001b[1;32m    196\u001b[0m \u001b[0;34m\u001b[0m\u001b[0m\n",
            "\u001b[0;31mApiTelegramException\u001b[0m: A request to the Telegram API was unsuccessful. Error code: 409. Description: Conflict: terminated by other getUpdates request; make sure that only one bot instance is running",
            "\nDuring handling of the above exception, another exception occurred:\n",
            "\u001b[0;31mKeyboardInterrupt\u001b[0m                         Traceback (most recent call last)",
            "\u001b[0;32m<ipython-input-27-4b36f17c7a63>\u001b[0m in \u001b[0;36m<cell line: 23>\u001b[0;34m()\u001b[0m\n\u001b[1;32m     21\u001b[0m \u001b[0;34m\u001b[0m\u001b[0m\n\u001b[1;32m     22\u001b[0m \u001b[0;34m\u001b[0m\u001b[0m\n\u001b[0;32m---> 23\u001b[0;31m \u001b[0mbot\u001b[0m\u001b[0;34m.\u001b[0m\u001b[0minfinity_polling\u001b[0m\u001b[0;34m(\u001b[0m\u001b[0;34m)\u001b[0m\u001b[0;34m\u001b[0m\u001b[0;34m\u001b[0m\u001b[0m\n\u001b[0m",
            "\u001b[0;32m/usr/local/lib/python3.10/dist-packages/telebot/__init__.py\u001b[0m in \u001b[0;36minfinity_polling\u001b[0;34m(self, timeout, skip_pending, long_polling_timeout, logger_level, allowed_updates, restart_on_change, path_to_watch, *args, **kwargs)\u001b[0m\n\u001b[1;32m   1088\u001b[0m         \u001b[0;32mwhile\u001b[0m \u001b[0;32mnot\u001b[0m \u001b[0mself\u001b[0m\u001b[0;34m.\u001b[0m\u001b[0m__stop_polling\u001b[0m\u001b[0;34m.\u001b[0m\u001b[0mis_set\u001b[0m\u001b[0;34m(\u001b[0m\u001b[0;34m)\u001b[0m\u001b[0;34m:\u001b[0m\u001b[0;34m\u001b[0m\u001b[0;34m\u001b[0m\u001b[0m\n\u001b[1;32m   1089\u001b[0m             \u001b[0;32mtry\u001b[0m\u001b[0;34m:\u001b[0m\u001b[0;34m\u001b[0m\u001b[0;34m\u001b[0m\u001b[0m\n\u001b[0;32m-> 1090\u001b[0;31m                 self.polling(non_stop=True, timeout=timeout, long_polling_timeout=long_polling_timeout,\n\u001b[0m\u001b[1;32m   1091\u001b[0m                              \u001b[0mlogger_level\u001b[0m\u001b[0;34m=\u001b[0m\u001b[0mlogger_level\u001b[0m\u001b[0;34m,\u001b[0m \u001b[0mallowed_updates\u001b[0m\u001b[0;34m=\u001b[0m\u001b[0mallowed_updates\u001b[0m\u001b[0;34m,\u001b[0m \u001b[0mrestart_on_change\u001b[0m\u001b[0;34m=\u001b[0m\u001b[0;32mFalse\u001b[0m\u001b[0;34m,\u001b[0m\u001b[0;34m\u001b[0m\u001b[0;34m\u001b[0m\u001b[0m\n\u001b[1;32m   1092\u001b[0m                              *args, **kwargs)\n",
            "\u001b[0;32m/usr/local/lib/python3.10/dist-packages/telebot/__init__.py\u001b[0m in \u001b[0;36mpolling\u001b[0;34m(self, non_stop, skip_pending, interval, timeout, long_polling_timeout, logger_level, allowed_updates, none_stop, restart_on_change, path_to_watch)\u001b[0m\n\u001b[1;32m   1176\u001b[0m \u001b[0;34m\u001b[0m\u001b[0m\n\u001b[1;32m   1177\u001b[0m         \u001b[0;32mif\u001b[0m \u001b[0mself\u001b[0m\u001b[0;34m.\u001b[0m\u001b[0mthreaded\u001b[0m\u001b[0;34m:\u001b[0m\u001b[0;34m\u001b[0m\u001b[0;34m\u001b[0m\u001b[0m\n\u001b[0;32m-> 1178\u001b[0;31m             self.__threaded_polling(non_stop=non_stop, interval=interval, timeout=timeout, long_polling_timeout=long_polling_timeout,\n\u001b[0m\u001b[1;32m   1179\u001b[0m                                     logger_level=logger_level, allowed_updates=allowed_updates)\n\u001b[1;32m   1180\u001b[0m         \u001b[0;32melse\u001b[0m\u001b[0;34m:\u001b[0m\u001b[0;34m\u001b[0m\u001b[0;34m\u001b[0m\u001b[0m\n",
            "\u001b[0;32m/usr/local/lib/python3.10/dist-packages/telebot/__init__.py\u001b[0m in \u001b[0;36m__threaded_polling\u001b[0;34m(self, non_stop, interval, timeout, long_polling_timeout, logger_level, allowed_updates)\u001b[0m\n\u001b[1;32m   1229\u001b[0m                         \u001b[0;31m# if logger_level and logger_level >= logging.INFO:   # enable in future releases. Change output to logger.error\u001b[0m\u001b[0;34m\u001b[0m\u001b[0;34m\u001b[0m\u001b[0m\n\u001b[1;32m   1230\u001b[0m                         \u001b[0mlogger\u001b[0m\u001b[0;34m.\u001b[0m\u001b[0minfo\u001b[0m\u001b[0;34m(\u001b[0m\u001b[0;34m\"Waiting for {0} seconds until retry\"\u001b[0m\u001b[0;34m.\u001b[0m\u001b[0mformat\u001b[0m\u001b[0;34m(\u001b[0m\u001b[0merror_interval\u001b[0m\u001b[0;34m)\u001b[0m \u001b[0;34m+\u001b[0m \u001b[0mwarning\u001b[0m\u001b[0;34m)\u001b[0m\u001b[0;34m\u001b[0m\u001b[0;34m\u001b[0m\u001b[0m\n\u001b[0;32m-> 1231\u001b[0;31m                         \u001b[0mtime\u001b[0m\u001b[0;34m.\u001b[0m\u001b[0msleep\u001b[0m\u001b[0;34m(\u001b[0m\u001b[0merror_interval\u001b[0m\u001b[0;34m)\u001b[0m\u001b[0;34m\u001b[0m\u001b[0;34m\u001b[0m\u001b[0m\n\u001b[0m\u001b[1;32m   1232\u001b[0m                         \u001b[0;32mif\u001b[0m \u001b[0merror_interval\u001b[0m \u001b[0;34m*\u001b[0m \u001b[0;36m2\u001b[0m \u001b[0;34m<\u001b[0m \u001b[0;36m60\u001b[0m\u001b[0;34m:\u001b[0m\u001b[0;34m\u001b[0m\u001b[0;34m\u001b[0m\u001b[0m\n\u001b[1;32m   1233\u001b[0m                             \u001b[0merror_interval\u001b[0m \u001b[0;34m*=\u001b[0m \u001b[0;36m2\u001b[0m\u001b[0;34m\u001b[0m\u001b[0;34m\u001b[0m\u001b[0m\n",
            "\u001b[0;31mKeyboardInterrupt\u001b[0m: "
          ]
        }
      ]
    },
    {
      "cell_type": "code",
      "source": [
        "word= \"Я не очень люблю делать домашнюю работу\"\n",
        "print(len(word))\n",
        "a = len(word)"
      ],
      "metadata": {
        "colab": {
          "base_uri": "https://localhost:8080/"
        },
        "id": "AszoXeEKqkQz",
        "outputId": "c561e43f-2f89-477d-9dd4-8cbc2dc825a7"
      },
      "execution_count": null,
      "outputs": [
        {
          "output_type": "stream",
          "name": "stdout",
          "text": [
            "39\n"
          ]
        }
      ]
    }
  ]
}